Traceback (most recent call last):
  File "/opt/hostedtoolcache/Python/3.12.11/x64/lib/python3.12/site-packages/jupyter_core/utils/__init__.py", line 154, in wrapped
    asyncio.get_running_loop()
RuntimeError: no running event loop

During handling of the above exception, another exception occurred:

Traceback (most recent call last):
  File "/opt/hostedtoolcache/Python/3.12.11/x64/lib/python3.12/site-packages/jupyter_cache/executors/utils.py", line 58, in single_nb_execution
    executenb(
  File "/opt/hostedtoolcache/Python/3.12.11/x64/lib/python3.12/site-packages/nbclient/client.py", line 1319, in execute
    return NotebookClient(nb=nb, resources=resources, km=km, **kwargs).execute()
           ^^^^^^^^^^^^^^^^^^^^^^^^^^^^^^^^^^^^^^^^^^^^^^^^^^^^^^^^^^^^^^^^^^^^^
  File "/opt/hostedtoolcache/Python/3.12.11/x64/lib/python3.12/site-packages/jupyter_core/utils/__init__.py", line 158, in wrapped
    return loop.run_until_complete(inner)
           ^^^^^^^^^^^^^^^^^^^^^^^^^^^^^^
  File "/opt/hostedtoolcache/Python/3.12.11/x64/lib/python3.12/asyncio/base_events.py", line 691, in run_until_complete
    return future.result()
           ^^^^^^^^^^^^^^^
  File "/opt/hostedtoolcache/Python/3.12.11/x64/lib/python3.12/site-packages/nbclient/client.py", line 709, in async_execute
    await self.async_execute_cell(
  File "/opt/hostedtoolcache/Python/3.12.11/x64/lib/python3.12/site-packages/nbclient/client.py", line 1062, in async_execute_cell
    await self._check_raise_for_error(cell, cell_index, exec_reply)
  File "/opt/hostedtoolcache/Python/3.12.11/x64/lib/python3.12/site-packages/nbclient/client.py", line 918, in _check_raise_for_error
    raise CellExecutionError.from_cell_and_msg(cell, exec_reply_content)
nbclient.exceptions.CellExecutionError: An error occurred while executing the following cell:
------------------

# Number of samples
N = 400

# Samples in the unit square
samples = np.random.uniform(-1, 1, [N, 2])

# Which ones are inside the unit circle?
is_in_circle = (samples[:,0]**2 + samples[:, 1]**2) < 1
Î¸1 = good_samples[:, 0]
Î¸2 = good_samples[:, 1]
print('Variance of Î¸1 (estimated from samples): %.3f' % np.var(Î¸1))
------------------


[31m---------------------------------------------------------------------------[39m
[31mNameError[39m                                 Traceback (most recent call last)
[36mCell[39m[36m [39m[32mIn[5][39m[32m, line 9[39m
[32m      7[39m [38;5;66;03m# Which ones are inside the unit circle?[39;00m
[32m      8[39m is_in_circle = (samples[:,[32m0[39m]**[32m2[39m + samples[:, [32m1[39m]**[32m2[39m) < [32m1[39m
[32m----> [39m[32m9[39m Î¸1 = [43mgood_samples[49m[:, [32m0[39m]
[32m     10[39m Î¸2 = good_samples[:, [32m1[39m]
[32m     11[39m [38;5;28mprint[39m([33m'[39m[33mVariance of Î¸1 (estimated from samples): [39m[38;5;132;01m%.3f[39;00m[33m'[39m % np.var(Î¸1))

[31mNameError[39m: name 'good_samples' is not defined

